<?xml version="1.0" ?>

<robot name="quad">

  <properties arm="0.175" kf="6.11e-8" km="1.5e-9" thrust2weight="2" max_speed_kmh="50" gnd_eff_coeff="0" prop_radius="0" drag_coeff_xy="0" drag_coeff_z="0" dw_coeff_1="0" dw_coeff_2="0" dw_coeff_3="1"/>
  <!-- [GRASP hummingbird] properties arm="0.175" kf="6.11e-8" km="1.5e-9" thrust2weight="2"/ -->
  <!-- [GRASP nano quad] properties arm="0.0635" kf="2.0e-9" km="4.74e-12" thrust2weight="2"/ -->

  <link name="base_link">

    <inertial>
      <origin rpy="0 0 0" xyz="0 0 0"/>
      <mass value="0.5"/>
      <!-- [GRASP hummingbird] mass value="0.5"/ -->
      <!-- [GRASP nano quad] mass value="0.075"/ -->
      <inertia ixx="0.0023" ixy="0.0" ixz="0.0" iyy="0.0023" iyz="0.0" izz="0.004"/>
      <!-- [GRASP hummingbird] inertia ixx="0.0023" ixy="0.0" ixz="0.0" iyy="0.0023" iyz="0.0" izz="0.004"/ -->
      <!-- [GRASP nano quad] inertia ixx="4.28-5" ixy="0.0" ixz="0.0" iyy="4.28-5" iyz="0.0" izz="8.36-5"/ -->
    </inertial>

    <!-- links>
      <grap url="http://citeseerx.ist.psu.edu/viewdoc/download?doi=10.1.1.169.1687&rep=rep1&type=pdf" />
    </links -->

    <visual>
      <origin rpy="0 0 0" xyz="0 0 -0.02"/>
      <geometry>
        <mesh filename="./quad.obj" scale=".0875 .0875 .0875"/>
      </geometry>
      <material name="grey">
        <color rgba=".2 .2 .2 1"/>
      </material>
    </visual>

    <collision>
      <origin rpy="0 0 0" xyz="0 0 -0.075"/>
      <geometry>
        <cylinder radius=".25" length=".15"/>
      </geometry>
    </collision>

  </link>

  <link name="prop0_link">
    <inertial>
      <origin rpy="0 0 0" xyz="0.175 0 0"/>
      <mass value="0"/>
      <inertia ixx="0" ixy="0" ixz="0" iyy="0" iyz="0" izz="0"/>
    </inertial>
  </link>
  <joint name="prop0_joint" type="fixed">
    <parent link="base_link"/>
    <child link="prop0_link"/>
  </joint>

  <link name="prop1_link">
    <inertial>
      <origin rpy="0 0 0" xyz="0 0.175 0"/>
      <mass value="0"/>
      <inertia ixx="0" ixy="0" ixz="0" iyy="0" iyz="0" izz="0"/>
    </inertial>
  </link>
  <joint name="prop1_joint" type="fixed">
    <parent link="base_link"/>
    <child link="prop1_link"/>
  </joint>

  <link name="prop2_link">
    <inertial>
      <origin rpy="0 0 0" xyz="-0.175 0 0"/>
      <mass value="0"/>
      <inertia ixx="0" ixy="0" ixz="0" iyy="0" iyz="0" izz="0"/>
    </inertial>
  </link>
  <joint name="prop2_joint" type="fixed">
    <parent link="base_link"/>
    <child link="prop2_link"/>
  </joint>

  <link name="prop3_link">
    <inertial>
      <origin rpy="0 0 0" xyz="0 -0.175 0"/>
      <mass value="0"/>
      <inertia ixx="0" ixy="0" ixz="0" iyy="0" iyz="0" izz="0"/>
    </inertial>
  </link>
  <joint name="prop3_joint" type="fixed">
    <parent link="base_link"/>
    <child link="prop3_link"/>
  </joint>

  <link name="center_of_mass_link">
    <inertial>
      <origin rpy="0 0 0" xyz="0 0 0"/>
      <mass value="0"/>
      <inertia ixx="0" ixy="0" ixz="0" iyy="0" iyz="0" izz="0"/>
    </inertial>
  </link>
  <joint name="center_of_mass_joint" type="fixed">
    <parent link="base_link"/>
    <child link="center_of_mass_link"/>
  </joint>

    <!-- grasp arm -->
  <link name="link1">
  	<inertial>
      <origin rpy="0 0 0" xyz="0 0 0.02"/>
       <mass value="0.25"/>
       <inertia ixx="0.1" ixy="0" ixz="0" iyy="0.1" iyz="0" izz="0.1"/>
    </inertial>
    <visual>
      <origin xyz="0 0 0" rpy="0 0 0" />
      <geometry>
        <mesh filename="meshes/link1.STL" />
      </geometry>
      <material name="">
        <color rgba="0 0.627450980392157 0.235294117647059 1" />
      </material>
    </visual>
    <collision>
      <origin xyz="0 0 0" rpy="0 0 0" />
      <geometry>
        <mesh filename="meshes/link1.STL" />
      </geometry>
    </collision>
  </link>

  <joint name="joint1" type="revolute">
      <!-- origin xyz="0 0 0.06605" rpy="-0.010805 0 0" / -->
      <origin xyz="0 0 -0.03305" rpy="0 3.14 1.57" />
      <parent link="base_link" />
      <child link="link1" />
      <axis xyz="0 0 1" />
      <limit effort="30" velocity="1.0" lower="-1.5708" upper="1.5708"/>
  </joint>


  <link name="camera_base">
  	<inertial>
      <origin rpy="0 0 0" xyz="0 0 0.02"/>
       <mass value="0.25"/>
       <inertia ixx="0.1" ixy="0" ixz="0" iyy="0.1" iyz="0" izz="0.1"/>
    </inertial>
    <visual>
      <origin xyz="0 0 0" rpy="0 0 0" />
      <geometry>
          <mesh filename="meshes/link4.STL" />
      </geometry>
      <material name="">
          <color rgba="0.592156862745098 0.666666666666667 0.682352941176471 1" />
      </material>
    </visual>
    <collision>
      <origin xyz="0 0 0" rpy="0 0 0" />
      <geometry>
          <mesh filename="meshes/link4.STL" />
      </geometry>
    </collision>
    <inertial>
      <mass value="0.00001"/>
      <inertia ixx="0.1" ixy="0.0" ixz="0.0" iyy="0.0" iyz="0.0" izz="0.0"/>
    </inertial>
  </link>

  <joint name="joint2" type="revolute">
      <origin xyz="0 -0.00031873 0.04145" rpy="0 1.5708 0" />
      <parent link="link1" />
      <child link="camera_base" />
      <axis xyz="0 0 1" />
      <limit effort="30" velocity="1.0" lower="-1.5708" upper="1.5708"/>
  </joint>


  <!-- link 5 -->
  <link name="gripper">
  	<inertial>
      <origin rpy="0 0 0" xyz="0 0 0.02"/>
       <mass value="0.25"/>
       <inertia ixx="0.1" ixy="0" ixz="0" iyy="0.1" iyz="0" izz="0.1"/>
    </inertial>
    <visual>
      <origin xyz="0 0 0" rpy="0 0 0"/>
      <geometry>
          <mesh filename="meshes/link5.STL"/>
      </geometry>
      <material name="">
          <color rgba="1 1 1 1" />
      </material>
    </visual>
    <collision>
      <origin xyz="0 0 0" rpy="0 0 0" />
      <geometry>
          <mesh filename="meshes/link5.STL" />
      </geometry>
    </collision>
  </link>

  <!-- joint 5 -->
  <joint name="joint5" type="revolute">
      <origin xyz="-0.07385 -0.001 0" rpy="0 -1.57 0"/>
      <!-- <origin xyz="0.004 0.0125 0.02" rpy="0 -1.57 0"/> -->
      <axis xyz="0 0 1"/>
      <parent link="camera_base"/>
      <child link="gripper"/>
      <limit effort="30" velocity="1.0" lower="-1.5708" upper="3.1416"/>
  </joint>

  <!-- link 6 -->
  <link name="camera_lens">
      <visual>
          <origin xyz="0 0 0" rpy="0 0 0"/>
          <geometry>
              <mesh filename="meshes/camera_lens.STL"/>
          </geometry>
          <material name="">
              <color rgba="1 1 1 1" />
          </material>
      </visual>
      <collision>
          <origin xyz="0 0 0" rpy="0 0 0" />
          <geometry>
              <mesh filename="meshes/camera_lens.STL" />
          </geometry>
      </collision>
  </link>

  <!-- joint 6 -->
  <joint name="joint6" type="fixed">
      <origin xyz="-0.05385 -0.0645 -0.0075" rpy="0 -1.57 0"/>
      <!-- <origin xyz="0.004 -0.0625 0.003" rpy="0 0 0"/> -->
      <axis xyz="0 0 1"/>
      <parent link="camera_base"/>
      <child link="camera_lens"/>
      <limit effort="30" velocity="1.0" lower="-1.5708" upper="3.1416"/>
  </joint>

  <!-- link 7 -->
  <link name="camera_target">
      <visual>
          <origin xyz="0 0 0" rpy="0 0 0"/>
          <geometry>
              <mesh filename="meshes/camera_lens.STL"/>
          </geometry>
          <material name="">
              <color rgba="1 1 1 1" />
          </material>
      </visual>
      <!-- <collision>
          <origin xyz="0 0 0" rpy="0 0 0" />
          <geometry>
              <mesh filename="meshes/camera_lens.STL" />
          </geometry>
      </collision> -->
  </link>

  <!-- joint 7 -->
  <joint name="joint7" type="fixed">
      <!-- <origin xyz="-0.07385 -0.001 0" rpy="0 -1.57 0"/> -->
      <origin xyz="0 0 0.1" rpy="0 0 0"/>
      <axis xyz="0 0 1"/>
      <parent link="camera_lens"/>
      <child link="camera_target"/>
      <limit effort="30" velocity="1.0" lower="-1.5708" upper="3.1416"/>
  </joint>

  <!-- link 8 -->
  <link name="grasp_target">
      <visual>
          <origin xyz="0 0 0" rpy="0 0 0"/>
          <geometry>
              <mesh filename="meshes/camera_lens.STL"/>
          </geometry>
          <material name="">
              <color rgba="1 1 1 1" />
          </material>
      </visual>
      <!-- <collision>
          <origin xyz="0 0 0" rpy="0 0 0" />
          <geometry>
              <mesh filename="meshes/camera_lens.STL" />
          </geometry>
      </collision> -->
  </link>

  <!-- joint 8 -->
  <joint name="joint8" type="fixed">
      <!-- <origin xyz="-0.07385 -0.001 0" rpy="0 -1.57 0"/> -->
      <origin xyz="0 0.06 0.1" rpy="0 0 0"/>
      <axis xyz="0 0 1"/>
      <parent link="camera_lens"/>
      <child link="grasp_target"/>
      <limit effort="30" velocity="1.0" lower="-1.5708" upper="3.1416"/>
  </joint>


</robot>

